<?xml version="0.0" ?>
<robot name="frame">
    <!--    车架-->
    <link name="frameLink">
        <inertial>
            <origin rpy="1.57 0 0" xyz="0 0 0"/>
            <mass value="5.0"/>
            <inertia ixx="0.1" ixy="0" ixz="0" iyy="0.1" iyz="0" izz="0.1"/>
        </inertial>

        <visual>
            <origin rpy="1.57 0 0" xyz="0 0 0"/>
            <geometry>
                <mesh filename="files/frame_scaled_right.stl"/>
            </geometry>
            <material name="framemat0">
                <color rgba="0.9 0.4 0. 1"/>
            </material>
        </visual>

        <visual>
            <origin rpy="1.57 0 0" xyz="0 0 0"/>
            <geometry>
                <mesh filename="files/frame_scaled_left.stl"/>
            </geometry>
            <material name="framemat0">
                <color rgba="0.9 0.4 0. 1"/>
            </material>
        </visual>

        <collision>
            <origin rpy="1.57 0 0" xyz="0 0 0"/>
            <geometry>
                <mesh filename="files/frame_scaled_right.stl"/>
            </geometry>
        </collision>

        <collision>
            <origin rpy="1.57 0 0" xyz="0 0 0"/>
            <geometry>
                <mesh filename="files/frame_scaled_left.stl"/>
            </geometry>
        </collision>
    </link>

    <!--    车把-->
    <link name="handlebarLink">
        <inertial>
            <origin rpy="0 0 0" xyz="0 0 0"/>
            <mass value="0.5"/>
            <inertia ixx="0.1" ixy="0" ixz="0" iyy="0.1" iyz="0" izz="0.1"/>
        </inertial>

        <visual>
            <origin rpy=" -1.5089523943366046 0.017064611667450248 -1.57454489647697 "
                    xyz=" -0.03313875198364258 0.0 -0.23958677053451538"/>
            <geometry>
                <mesh filename="files/handlebar_scaled.stl"/>
            </geometry>
            <material name="framemat0">
                <color rgba="0.9 0.4 0. 1"/>
            </material>
        </visual>

        <collision>
            <origin rpy=" -1.5089523943366046 0.017064611667450248 -1.57454489647697 "
                    xyz=" -0.03313875198364258 0.0 -0.23958677053451538"/>
            <geometry>
                <mesh filename="files/handlebar_scaled.stl"/>
            </geometry>
        </collision>
    </link>

    <joint name="frame_to_handlebar" type="continuous">
        <axis xyz="0 0 1"/>
        <parent link="frameLink"/>
        <child link="handlebarLink"/>
        <origin rpy="0 -0.261799387799149 0" xyz="0.70  0  0.22"/>
        <limit effort="100" velocity="100"/>
        <joint_properties damping="0.0" friction="0.0"/>
    </joint>

<!--    <link name="camera">-->
<!--        <visual>-->
<!--            <geometry>-->
<!--                <box size="0.05 0.20 0.05"/> &lt;!&ndash; 或者使用球体 <sphere radius="0.05"/> &ndash;&gt;-->
<!--            </geometry>-->
<!--            <material name="camera_material">-->
<!--                <color rgba="0 0 1 1"/> &lt;!&ndash; 红色表示相机位置 &ndash;&gt;-->
<!--            </material>-->
<!--        </visual>-->
<!--        <collision>-->
<!--            <geometry>-->
<!--                <box size="0.05 0.05 0.05"/>-->
<!--            </geometry>-->
<!--        </collision>-->
<!--        <inertial>-->
<!--            <mass value="0"/>-->
<!--            <inertia ixx="0" iyy="0" izz="0"/>-->
<!--        </inertial>-->
<!--    </link>-->

    <!-- 约束相机与车把手的相对位置 -->
<!--    <joint name="camera_joint" type="fixed">-->
<!--        <parent link="handlebarLink" />-->
<!--        <child link="camera" />-->
<!--        <origin xyz="0.2 0 0.2" rpy="0 0 0"/> &lt;!&ndash; 根据需求调整位置和角度 &ndash;&gt;-->
<!--    </joint>-->

    <link name="frontWheelLink">
        <inertial>
            <origin rpy="1.57 0 0" xyz="0 0 0"/>
            <mass value="1.0"/>
            <inertia ixx="0.1" ixy="0" ixz="0" iyy="0.1" iyz="0" izz="0.1"/>
        </inertial>
        <visual>
            <origin rpy="1.57 0 0" xyz="0 0 0"/>
            <geometry>
                <mesh filename="files/wheel_scaled.stl"/>
            </geometry>
            <material name="framemat0">
                <color rgba="0.9 0.4 0. 1"/>
            </material>
        </visual>
        <collision>
            <origin rpy="1.57 0 0" xyz="0 0 0"/>
            <geometry>
                <mesh filename="files/wheel_scaled.stl"/>
            </geometry>
            <surface>
                <friction>
                    <ode>
                        <mu>0.8</mu>
                        <mu2>0.4</mu2>
                    </ode>
                </friction>
            </surface>
        </collision>
    </link>

    <joint name="handlebar_to_frontwheel" type="continuous">
        <axis xyz="0 1 0"/>
        <parent link="handlebarLink"/>
        <child link="frontWheelLink"/>
        <origin rpy="0 0 0" xyz="0.07, 0, -0.69"/>
        <limit effort="100" velocity="100"/>
        <joint_properties damping="0.0" friction="0.0"/>
    </joint>

    <!--后轮-->
    <link name="backWheelLink">
        <inertial>
            <origin rpy="1.57 0 0" xyz="0 0 0"/>
            <mass value="1.0"/>
            <inertia ixx="0.1" ixy="0" ixz="0" iyy="0.1" iyz="0" izz="0.1"/>
        </inertial>
        <visual>
            <origin rpy="1.57 0 0" xyz="0 0 0"/>
            <geometry>
                <mesh filename="files/wheel_scaled.stl"/>
            </geometry>
            <material name="framemat0">
                <color rgba="0.9 0.4 0. 1"/>
            </material>
        </visual>
        <collision>
            <origin rpy="1.57 0 0" xyz="0 0 0"/>
            <geometry>
                <mesh filename="files/wheel_scaled.stl"/>
            </geometry>
            <surface>
                <friction>
                    <ode>
                        <mu>0.8</mu>
                        <mu2>0.4</mu2>
                    </ode>
                </friction>
            </surface>
        </collision>
    </link>

    <joint name="frame_to_backwheel" type="continuous">
        <axis xyz="0 1 0"/>
        <parent link="frameLink"/>
        <child link="backWheelLink"/>
        <origin rpy="0 0 0" xyz="-0.69, 0, -0.42"/>
        <limit effort="100" velocity="100"/>
        <joint_properties damping="0.0" friction="0.0"/>
    </joint>

    <!--    飞轮-->
    <link name="flyWheel">
        <inertial>
            <origin rpy="1.57075 1.57075 0"/>
            <mass value="4.0"/>
            <inertia ixx="0.5" ixy="0" ixz="0" iyy="0.5" iyz="0.0" izz="0.5"/>
        </inertial>
        <visual>
            <geometry>
                <cylinder length="0.06" radius="0.2"/>
            </geometry>
            <origin rpy="1.57075 0 1.57075" xyz="-0.1 0 0"/>
        </visual>
        <collision>
            <geometry>
                <cylinder length="0.06" radius="0.2"/>
            </geometry>
            <origin rpy="1.57075 1.57075 0"/>
        </collision>
    </link>

    <joint name="flyWheelLink_to_flyWheel" type="continuous">
        <axis xyz="1 0 0"/>
        <parent link="flyWheelLink"/>
        <child link="flyWheel"/>
        <origin rpy="0 0 0" xyz="0 0 0.2"/>
    </joint>

    <link name="flyWheelLink">
        <inertial>
            <origin rpy="1.57075 1.57075 0"/>
            <mass value="0.0"/>
            <inertia ixx="0.4" ixy="0" ixz="0" iyy="0.4" iyz="0.0" izz="0.2"/>
        </inertial>
        <visual>
            <geometry>
                <cylinder length="0.12" radius="0.03"/>
            </geometry>
            <origin rpy="1.57075 0 1.57075" xyz="-0.15 0 0.2"/>
        </visual>
        <collision>
            <geometry>
                <cylinder length="0.05" radius="0.2"/>
            </geometry>
            <origin rpy="1.57075 1.57075 0"/>
        </collision>
    </link>

    <joint name="frame_to_flyWheelLink" type="fixed">
        <axis xyz="0 1 0"/>
        <parent link="frameLink"/>
        <child link="flyWheelLink"/>
        <origin rpy="0 0 0" xyz="0, 0, 0"/>
    </joint>

    <!--    陀螺仪-->
    <link name="gyros">
        <inertial>
            <origin rpy="0 0 0"/>
            <mass value="0.0"/>
            <inertia ixx="0" ixy="0" ixz="0" iyy="0" iyz="0" izz="0"/>
        </inertial>
        <visual>
            <geometry>
                <box size="0.1 0.1 0.1"/>
                <origin rpy="0 0 0" xyz="0 0 0"/>
            </geometry>
            <!--            隐藏陀螺仪-->
            <material name="transparent">
                <color rgba="0 0 0 0"/>
            </material>
        </visual>
    </link>

    <joint name="frame_to_gyros" type="fixed">
        <!--    axis标签用于指定关节的运动轴   xyz="0 1 0"表示关节围绕Y轴旋转或沿Y轴移动 -->
        <axis xyz="0 1 0"/>
        <parent link="frameLink"/>
        <child link="gyros"/>
        <origin rpy="0 0 0" xyz="0, 0, 0"/>
    </joint>

</robot>

